<?xml version="1.0" encoding="UTF-8"?>
<!-- Generated by org.testng.reporters.JUnitReportReporter -->
<testsuite hostname="BSA-Laptop" failures="5" tests="18" name="com.AARestAssuredAPI.testcases.Post_NewRecord_intoDatabase" time="0.053" errors="0" timestamp="2023-06-23T21:47:45 IST" skipped="10">
  <testcase classname="com.AARestAssuredAPI.testcases.Post_NewRecord_intoDatabase" name="checkStatusCode" time="0.002">
    <failure message="expected [200] but found [429]" type="java.lang.AssertionError">
      <![CDATA[java.lang.AssertionError: expected [200] but found [429]
at org.testng.Assert.fail(Assert.java:99)
at org.testng.Assert.failNotEquals(Assert.java:1037)
at org.testng.Assert.assertEqualsImpl(Assert.java:140)
at org.testng.Assert.assertEquals(Assert.java:122)
at org.testng.Assert.assertEquals(Assert.java:907)
at org.testng.Assert.assertEquals(Assert.java:917)
at com.AARestAssuredAPI.testcases.Post_NewRecord_intoDatabase.checkStatusCode(Post_NewRecord_intoDatabase.java:56)
at java.base/jdk.internal.reflect.NativeMethodAccessorImpl.invoke0(Native Method)
at java.base/jdk.internal.reflect.NativeMethodAccessorImpl.invoke(NativeMethodAccessorImpl.java:62)
at java.base/jdk.internal.reflect.DelegatingMethodAccessorImpl.invoke(DelegatingMethodAccessorImpl.java:43)
at java.base/java.lang.reflect.Method.invoke(Method.java:566)
at org.testng.internal.MethodInvocationHelper.invokeMethod(MethodInvocationHelper.java:133)
at org.testng.internal.TestInvoker.invokeMethod(TestInvoker.java:598)
at org.testng.internal.TestInvoker.retryFailed(TestInvoker.java:213)
at org.testng.internal.MethodRunner.runInSequence(MethodRunner.java:58)
at org.testng.internal.TestInvoker$MethodInvocationAgent.invoke(TestInvoker.java:824)
at org.testng.internal.TestInvoker.invokeTestMethods(TestInvoker.java:146)
at org.testng.internal.TestMethodWorker.invokeTestMethods(TestMethodWorker.java:146)
at org.testng.internal.TestMethodWorker.run(TestMethodWorker.java:128)
at java.base/java.util.ArrayList.forEach(ArrayList.java:1541)
at org.testng.TestRunner.privateRun(TestRunner.java:794)
at org.testng.TestRunner.run(TestRunner.java:596)
at org.testng.SuiteRunner.runTest(SuiteRunner.java:377)
at org.testng.SuiteRunner.runSequentially(SuiteRunner.java:371)
at org.testng.SuiteRunner.privateRun(SuiteRunner.java:332)
at org.testng.SuiteRunner.run(SuiteRunner.java:276)
at org.testng.SuiteRunnerWorker.runSuite(SuiteRunnerWorker.java:53)
at org.testng.SuiteRunnerWorker.run(SuiteRunnerWorker.java:96)
at org.testng.TestNG.runSuitesSequentially(TestNG.java:1212)
at org.testng.TestNG.runSuitesLocally(TestNG.java:1134)
at org.testng.TestNG.runSuites(TestNG.java:1063)
at org.testng.TestNG.run(TestNG.java:1031)
at org.testng.remote.AbstractRemoteTestNG.run(AbstractRemoteTestNG.java:115)
at org.testng.remote.RemoteTestNG.initAndRun(RemoteTestNG.java:251)
at org.testng.remote.RemoteTestNG.main(RemoteTestNG.java:77)
]]>
    </failure>
  </testcase> <!-- checkStatusCode -->
  <system-out/>
  <testcase classname="com.AARestAssuredAPI.testcases.Post_NewRecord_intoDatabase" name="checkContentType" time="0.002">
    <skipped/>
  </testcase> <!-- checkContentType -->
  <system-out/>
  <testcase classname="com.AARestAssuredAPI.testcases.Post_NewRecord_intoDatabase" name="checkstatusLine" time="0.001">
    <skipped/>
  </testcase> <!-- checkstatusLine -->
  <system-out/>
  <testcase classname="com.AARestAssuredAPI.testcases.Post_NewRecord_intoDatabase" name="checkcontentLength" time="0.006"/>
  <system-out/>
  <testcase classname="com.AARestAssuredAPI.testcases.Post_NewRecord_intoDatabase" name="checkResponseBody" time="0.002">
    <failure message="expected [true] but found [false]" type="java.lang.AssertionError">
      <![CDATA[java.lang.AssertionError: expected [true] but found [false]
at org.testng.Assert.fail(Assert.java:99)
at org.testng.Assert.failNotEquals(Assert.java:1037)
at org.testng.Assert.assertEqualsImpl(Assert.java:140)
at org.testng.Assert.assertEquals(Assert.java:122)
at org.testng.Assert.assertEquals(Assert.java:819)
at org.testng.Assert.assertEquals(Assert.java:829)
at com.AARestAssuredAPI.testcases.Post_NewRecord_intoDatabase.checkResponseBody(Post_NewRecord_intoDatabase.java:46)
at java.base/jdk.internal.reflect.NativeMethodAccessorImpl.invoke0(Native Method)
at java.base/jdk.internal.reflect.NativeMethodAccessorImpl.invoke(NativeMethodAccessorImpl.java:62)
at java.base/jdk.internal.reflect.DelegatingMethodAccessorImpl.invoke(DelegatingMethodAccessorImpl.java:43)
at java.base/java.lang.reflect.Method.invoke(Method.java:566)
at org.testng.internal.MethodInvocationHelper.invokeMethod(MethodInvocationHelper.java:133)
at org.testng.internal.TestInvoker.invokeMethod(TestInvoker.java:598)
at org.testng.internal.TestInvoker.retryFailed(TestInvoker.java:213)
at org.testng.internal.MethodRunner.runInSequence(MethodRunner.java:58)
at org.testng.internal.TestInvoker$MethodInvocationAgent.invoke(TestInvoker.java:824)
at org.testng.internal.TestInvoker.invokeTestMethods(TestInvoker.java:146)
at org.testng.internal.TestMethodWorker.invokeTestMethods(TestMethodWorker.java:146)
at org.testng.internal.TestMethodWorker.run(TestMethodWorker.java:128)
at java.base/java.util.ArrayList.forEach(ArrayList.java:1541)
at org.testng.TestRunner.privateRun(TestRunner.java:794)
at org.testng.TestRunner.run(TestRunner.java:596)
at org.testng.SuiteRunner.runTest(SuiteRunner.java:377)
at org.testng.SuiteRunner.runSequentially(SuiteRunner.java:371)
at org.testng.SuiteRunner.privateRun(SuiteRunner.java:332)
at org.testng.SuiteRunner.run(SuiteRunner.java:276)
at org.testng.SuiteRunnerWorker.runSuite(SuiteRunnerWorker.java:53)
at org.testng.SuiteRunnerWorker.run(SuiteRunnerWorker.java:96)
at org.testng.TestNG.runSuitesSequentially(TestNG.java:1212)
at org.testng.TestNG.runSuitesLocally(TestNG.java:1134)
at org.testng.TestNG.runSuites(TestNG.java:1063)
at org.testng.TestNG.run(TestNG.java:1031)
at org.testng.remote.AbstractRemoteTestNG.run(AbstractRemoteTestNG.java:115)
at org.testng.remote.RemoteTestNG.initAndRun(RemoteTestNG.java:251)
at org.testng.remote.RemoteTestNG.main(RemoteTestNG.java:77)
]]>
    </failure>
  </testcase> <!-- checkResponseBody -->
  <system-out/>
  <testcase classname="com.AARestAssuredAPI.testcases.Post_NewRecord_intoDatabase" name="checkContentType" time="0.003">
    <skipped/>
  </testcase> <!-- checkContentType -->
  <system-out/>
  <testcase classname="com.AARestAssuredAPI.testcases.Post_NewRecord_intoDatabase" name="checkContentType" time="0.001">
    <failure message="expected [text/html;chartset=UTF-8] but found [text/html; charset=UTF-8]" type="java.lang.AssertionError">
      <![CDATA[java.lang.AssertionError: expected [text/html;chartset=UTF-8] but found [text/html; charset=UTF-8]
at org.testng.Assert.fail(Assert.java:99)
at org.testng.Assert.failNotEquals(Assert.java:1037)
at org.testng.Assert.assertEqualsImpl(Assert.java:140)
at org.testng.Assert.assertEquals(Assert.java:122)
at org.testng.Assert.assertEquals(Assert.java:629)
at org.testng.Assert.assertEquals(Assert.java:639)
at com.AARestAssuredAPI.testcases.Post_NewRecord_intoDatabase.checkContentType(Post_NewRecord_intoDatabase.java:84)
at java.base/jdk.internal.reflect.NativeMethodAccessorImpl.invoke0(Native Method)
at java.base/jdk.internal.reflect.NativeMethodAccessorImpl.invoke(NativeMethodAccessorImpl.java:62)
at java.base/jdk.internal.reflect.DelegatingMethodAccessorImpl.invoke(DelegatingMethodAccessorImpl.java:43)
at java.base/java.lang.reflect.Method.invoke(Method.java:566)
at org.testng.internal.MethodInvocationHelper.invokeMethod(MethodInvocationHelper.java:133)
at org.testng.internal.TestInvoker.invokeMethod(TestInvoker.java:598)
at org.testng.internal.TestInvoker.retryFailed(TestInvoker.java:213)
at org.testng.internal.MethodRunner.runInSequence(MethodRunner.java:58)
at org.testng.internal.TestInvoker$MethodInvocationAgent.invoke(TestInvoker.java:824)
at org.testng.internal.TestInvoker.invokeTestMethods(TestInvoker.java:146)
at org.testng.internal.TestMethodWorker.invokeTestMethods(TestMethodWorker.java:146)
at org.testng.internal.TestMethodWorker.run(TestMethodWorker.java:128)
at java.base/java.util.ArrayList.forEach(ArrayList.java:1541)
at org.testng.TestRunner.privateRun(TestRunner.java:794)
at org.testng.TestRunner.run(TestRunner.java:596)
at org.testng.SuiteRunner.runTest(SuiteRunner.java:377)
at org.testng.SuiteRunner.runSequentially(SuiteRunner.java:371)
at org.testng.SuiteRunner.privateRun(SuiteRunner.java:332)
at org.testng.SuiteRunner.run(SuiteRunner.java:276)
at org.testng.SuiteRunnerWorker.runSuite(SuiteRunnerWorker.java:53)
at org.testng.SuiteRunnerWorker.run(SuiteRunnerWorker.java:96)
at org.testng.TestNG.runSuitesSequentially(TestNG.java:1212)
at org.testng.TestNG.runSuitesLocally(TestNG.java:1134)
at org.testng.TestNG.runSuites(TestNG.java:1063)
at org.testng.TestNG.run(TestNG.java:1031)
at org.testng.remote.AbstractRemoteTestNG.run(AbstractRemoteTestNG.java:115)
at org.testng.remote.RemoteTestNG.initAndRun(RemoteTestNG.java:251)
at org.testng.remote.RemoteTestNG.main(RemoteTestNG.java:77)
]]>
    </failure>
  </testcase> <!-- checkContentType -->
  <system-out/>
  <testcase classname="com.AARestAssuredAPI.testcases.Post_NewRecord_intoDatabase" name="checkResponseBody" time="0.003">
    <skipped/>
  </testcase> <!-- checkResponseBody -->
  <system-out/>
  <testcase classname="com.AARestAssuredAPI.testcases.Post_NewRecord_intoDatabase" name="checkserverType" time="0.003">
    <failure message="expected [nginx/1.21.6] but found [Apache]" type="java.lang.AssertionError">
      <![CDATA[java.lang.AssertionError: expected [nginx/1.21.6] but found [Apache]
at org.testng.Assert.fail(Assert.java:99)
at org.testng.Assert.failNotEquals(Assert.java:1037)
at org.testng.Assert.assertEqualsImpl(Assert.java:140)
at org.testng.Assert.assertEquals(Assert.java:122)
at org.testng.Assert.assertEquals(Assert.java:629)
at org.testng.Assert.assertEquals(Assert.java:639)
at com.AARestAssuredAPI.testcases.Post_NewRecord_intoDatabase.checkserverType(Post_NewRecord_intoDatabase.java:94)
at java.base/jdk.internal.reflect.NativeMethodAccessorImpl.invoke0(Native Method)
at java.base/jdk.internal.reflect.NativeMethodAccessorImpl.invoke(NativeMethodAccessorImpl.java:62)
at java.base/jdk.internal.reflect.DelegatingMethodAccessorImpl.invoke(DelegatingMethodAccessorImpl.java:43)
at java.base/java.lang.reflect.Method.invoke(Method.java:566)
at org.testng.internal.MethodInvocationHelper.invokeMethod(MethodInvocationHelper.java:133)
at org.testng.internal.TestInvoker.invokeMethod(TestInvoker.java:598)
at org.testng.internal.TestInvoker.retryFailed(TestInvoker.java:213)
at org.testng.internal.MethodRunner.runInSequence(MethodRunner.java:58)
at org.testng.internal.TestInvoker$MethodInvocationAgent.invoke(TestInvoker.java:824)
at org.testng.internal.TestInvoker.invokeTestMethods(TestInvoker.java:146)
at org.testng.internal.TestMethodWorker.invokeTestMethods(TestMethodWorker.java:146)
at org.testng.internal.TestMethodWorker.run(TestMethodWorker.java:128)
at java.base/java.util.ArrayList.forEach(ArrayList.java:1541)
at org.testng.TestRunner.privateRun(TestRunner.java:794)
at org.testng.TestRunner.run(TestRunner.java:596)
at org.testng.SuiteRunner.runTest(SuiteRunner.java:377)
at org.testng.SuiteRunner.runSequentially(SuiteRunner.java:371)
at org.testng.SuiteRunner.privateRun(SuiteRunner.java:332)
at org.testng.SuiteRunner.run(SuiteRunner.java:276)
at org.testng.SuiteRunnerWorker.runSuite(SuiteRunnerWorker.java:53)
at org.testng.SuiteRunnerWorker.run(SuiteRunnerWorker.java:96)
at org.testng.TestNG.runSuitesSequentially(TestNG.java:1212)
at org.testng.TestNG.runSuitesLocally(TestNG.java:1134)
at org.testng.TestNG.runSuites(TestNG.java:1063)
at org.testng.TestNG.run(TestNG.java:1031)
at org.testng.remote.AbstractRemoteTestNG.run(AbstractRemoteTestNG.java:115)
at org.testng.remote.RemoteTestNG.initAndRun(RemoteTestNG.java:251)
at org.testng.remote.RemoteTestNG.main(RemoteTestNG.java:77)
]]>
    </failure>
  </testcase> <!-- checkserverType -->
  <system-out/>
  <testcase classname="com.AARestAssuredAPI.testcases.Post_NewRecord_intoDatabase" name="checkstatusLine" time="0.001">
    <failure message="expected [HTTP/1.1 200 OK] but found [HTTP/1.1 429 Too Many Requests]" type="java.lang.AssertionError">
      <![CDATA[java.lang.AssertionError: expected [HTTP/1.1 200 OK] but found [HTTP/1.1 429 Too Many Requests]
at org.testng.Assert.fail(Assert.java:99)
at org.testng.Assert.failNotEquals(Assert.java:1037)
at org.testng.Assert.assertEqualsImpl(Assert.java:140)
at org.testng.Assert.assertEquals(Assert.java:122)
at org.testng.Assert.assertEquals(Assert.java:629)
at org.testng.Assert.assertEquals(Assert.java:639)
at com.AARestAssuredAPI.testcases.Post_NewRecord_intoDatabase.checkstatusLine(Post_NewRecord_intoDatabase.java:75)
at java.base/jdk.internal.reflect.NativeMethodAccessorImpl.invoke0(Native Method)
at java.base/jdk.internal.reflect.NativeMethodAccessorImpl.invoke(NativeMethodAccessorImpl.java:62)
at java.base/jdk.internal.reflect.DelegatingMethodAccessorImpl.invoke(DelegatingMethodAccessorImpl.java:43)
at java.base/java.lang.reflect.Method.invoke(Method.java:566)
at org.testng.internal.MethodInvocationHelper.invokeMethod(MethodInvocationHelper.java:133)
at org.testng.internal.TestInvoker.invokeMethod(TestInvoker.java:598)
at org.testng.internal.TestInvoker.retryFailed(TestInvoker.java:213)
at org.testng.internal.MethodRunner.runInSequence(MethodRunner.java:58)
at org.testng.internal.TestInvoker$MethodInvocationAgent.invoke(TestInvoker.java:824)
at org.testng.internal.TestInvoker.invokeTestMethods(TestInvoker.java:146)
at org.testng.internal.TestMethodWorker.invokeTestMethods(TestMethodWorker.java:146)
at org.testng.internal.TestMethodWorker.run(TestMethodWorker.java:128)
at java.base/java.util.ArrayList.forEach(ArrayList.java:1541)
at org.testng.TestRunner.privateRun(TestRunner.java:794)
at org.testng.TestRunner.run(TestRunner.java:596)
at org.testng.SuiteRunner.runTest(SuiteRunner.java:377)
at org.testng.SuiteRunner.runSequentially(SuiteRunner.java:371)
at org.testng.SuiteRunner.privateRun(SuiteRunner.java:332)
at org.testng.SuiteRunner.run(SuiteRunner.java:276)
at org.testng.SuiteRunnerWorker.runSuite(SuiteRunnerWorker.java:53)
at org.testng.SuiteRunnerWorker.run(SuiteRunnerWorker.java:96)
at org.testng.TestNG.runSuitesSequentially(TestNG.java:1212)
at org.testng.TestNG.runSuitesLocally(TestNG.java:1134)
at org.testng.TestNG.runSuites(TestNG.java:1063)
at org.testng.TestNG.run(TestNG.java:1031)
at org.testng.remote.AbstractRemoteTestNG.run(AbstractRemoteTestNG.java:115)
at org.testng.remote.RemoteTestNG.initAndRun(RemoteTestNG.java:251)
at org.testng.remote.RemoteTestNG.main(RemoteTestNG.java:77)
]]>
    </failure>
  </testcase> <!-- checkstatusLine -->
  <system-out/>
  <testcase classname="com.AARestAssuredAPI.testcases.Post_NewRecord_intoDatabase" name="checkResponseBody" time="0.012">
    <skipped/>
  </testcase> <!-- checkResponseBody -->
  <system-out/>
  <testcase classname="com.AARestAssuredAPI.testcases.Post_NewRecord_intoDatabase" name="checkStatusCode" time="0.001">
    <skipped/>
  </testcase> <!-- checkStatusCode -->
  <system-out/>
  <testcase classname="com.AARestAssuredAPI.testcases.Post_NewRecord_intoDatabase" name="checkserverType" time="0.001">
    <skipped/>
  </testcase> <!-- checkserverType -->
  <system-out/>
  <testcase classname="com.AARestAssuredAPI.testcases.Post_NewRecord_intoDatabase" name="checkserverType" time="0.004">
    <skipped/>
  </testcase> <!-- checkserverType -->
  <system-out/>
  <testcase classname="com.AARestAssuredAPI.testcases.Post_NewRecord_intoDatabase" name="checkstatusLine" time="0.002">
    <skipped/>
  </testcase> <!-- checkstatusLine -->
  <system-out/>
  <testcase classname="com.AARestAssuredAPI.testcases.Post_NewRecord_intoDatabase" name="checkResponseTime" time="0.003"/>
  <system-out/>
  <testcase classname="com.AARestAssuredAPI.testcases.Post_NewRecord_intoDatabase" name="checkcontentEncoding" time="0.005"/>
  <system-out/>
  <testcase classname="com.AARestAssuredAPI.testcases.Post_NewRecord_intoDatabase" name="checkStatusCode" time="0.001">
    <skipped/>
  </testcase> <!-- checkStatusCode -->
  <system-out/>
</testsuite> <!-- com.AARestAssuredAPI.testcases.Post_NewRecord_intoDatabase -->
